Workbook

Sheet STOCK
A1: NO | B1: KDTK | C1: NAMA | D1: STOK
A2: 1 | B2: FW28 | C2: NGURAH RAI_KELUNGKUNG | D2: 435127899
A3: =A2+1 -> 2 | B3: T6Q3 | C3: PC.PC.BY PASS NGURAH RAI KUTA BDG | D3: 751036373
A4: =A3+1 -> 3 | B4: TLA3 | C4: PC.PC.NEGARA 2 - JEMBRANA | D4: 784020993
A5: =A4+1 -> 4 | B5: T301 | C5: PC.PC.DEWI SRI 18 - BADUNG | D5: 580786353
A6: =A5+1 -> 5 | B6: TQ45 | C6: PC.PC.MUNGGU - BADUNG | D6: 764297741
A7: =A6+1 -> 6 | B7: TA6A | C7: PC.PC.TANDEG – BADUNG | D7: 787257760
A8: =A7+1 -> 7 | B8: TD99 | C8: PC.PC.GATSU BARAT - DENPASAR | D8: 693435433
A9: =A8+1 -> 8 | B9: TKV3 | C9: PC.PC.PECATU - BADUNG | D9: 762285846
A10: =A9+1 -> 9 | B10: TRGI | C10: BAJERA - TABANAN | D10: 751479256
A11: =A10+1 -> 10 | B11: TA8H | C11: PC.PC.PECATU INDAH - BADUNG | D11: 762301695
A12: =A11+1 -> 11 | B12: TNAF | C12: PC.PC.RAYA PADONAN 25 - BADUNG | D12: 744960541
A13: =A12+1 -> 12 | B13: T1MN | C13: PC.PC.MENGWITANI - BADUNG | D13: 736426820
A14: =A13+1 -> 13 | B14: TCIT | C14: PC.PC.DALUNG - BADUNG | D14: 746247308
... A42: =A41+1 -> 41 | B42: T8LJ | C42: PC.PC.DANAU TAMBLINGAN - DENPASAR | D42: 637014936
A43: =A42+1 -> 42 | B43: TZEM | C43: PC.PC.DHARMAWANGSA 64 - BADUNG | D43: #N/A
A44: =A43+1 -> 43 | B44: TQW4 | C44: PC.GUNUNG RINJANI NO.3 DPS | D44: 649585976
A45: =A44+1 -> 44 | B45: TL9C | C45: PC.PC.CANDIDASA - KARANGASEM | D45: 621126188
A46: =A45+1 -> 45 | B46: TCK4 | C46: YCG.SADING - BADUNG | D46: 679352320
A47: =A46+1 -> 46 | B47: TF66 | C47: PC.PC.UBUD - GIANYAR | D47: 587152186
A48: =A47+1 -> 47 | B48: F0VA | C48: TULAMBEN - KARANGASEM | D48: 642596960
A49: =A48+1 -> 48 | B49: TENE | C49: PC.PC.TUKAD BATANGHARI - DENPASAR | D49: 581701384
A50: =A49+1 -> 49 | B50: T8P8 | C50: PC.PC.SERIRIT - SINGARAJA | D50: 627597226
A51: =A50+1 -> 50 | B51: T8BU | C51: FRESH CARGO PERMAI - DENPASAR | D51: 605746954
A52: =A51+1 -> 51 | B52: TR0F | C52: PC.YEH MALET - KARANGASEM | D52: 576217617
A53: =A52+1 -> 52 | B53: FUZ6 | C53: PULAU MENJANGAN - TABANAN | D53: 554753133
A54: =A53+1 -> 53 | B54: FAH8 | C54: PC.PC.RAYA PUNCAK MANGGU - BDG | D54: 652843769
A55: =A54+1 -> 54 | B55: TZDG | C55: PC.KEBO IWA UTARA NO. 2 - DPS | D55: 560229702
... A147: =A146+1 -> 146 | B147: TQCW | C147: PC.BR SAYAN BALERAN - BADUNG | D147: 528043546
A148: =A147+1 -> 147 | B148: TSAP | C148: BONDALEM - SINGARAJA | D148: #N/A
A149: =A148+1 -> 148 | B149: FUDU | C149: BANYUATIS - SINGARAJA | D149: 555818608
A150: =A149+1 -> 149 | B150: FJZX | C150: PC.ABIMAYU_TABANAN | D150: 511722392
A151: =A150+1 -> 150 | B151: TVCI | C151: YCG.KALIBUKBUK - SINGARAJA | D151: 560202175
A152: =A151+1 -> 151 | B152: TQBJ | C152: PC.PC.TOHPATI KESIMAN - DENPASAR | D152: 555634072
A153: =A152+1 -> 152 | B153: TDVX | C153: KEDONGANAN - BADUNG | D153: 527096011
A154: =A153+1 -> 153 | B154: FJHJ | C154: NGURAH RAI - BADUNG | D154: 572574132
A155: =A154+1 -> 154 | B155: TVZL | C155: SUNSET ROAD 37 - BADUNG | D155: 557781184
A156: =A155+1 -> 155 | B156: F8I6 | C156: BATURITI - TABANAN | D156: 562665829
A157: =A156+1 -> 156 | B157: TIHR | C157: NAKULA - BADUNG | D157: 493424736
A158: =A157+1 -> 157 | B158: T69T | C158: PEMARON MUNGGU - BADUNG | D158: 449748424
...

Sheet ALL TOKO (2)
A1: senin | B1: selasa | C1: rabu | E1: jumat
A2: NO | B2: kdtk | C2: nama | D2: sal | E2: will | G2: JUL,AGST,SEPT'26 | H2: SO MEI | I2: SO JUNI | J2: SO JULI | K2: SO AGUSTUS | L2: ket | O2: ZONA | U2: 8 | V2: 4 | W2: =V2*12 -> 48 | X2: 26 | Y2: =W2+X2 -> 74
A4: 1 | B4: TDVX | C4: KEDONGANAN - BADUNG | D4: 546017415 | E4: Kedonganan | F4: BADUNG | G4: M | J4: 46207 | K4: =IFERROR(VLOOKUP(B4,#REF!,4,0),"") | L4: angga | M4: STANDART NEW
A5: =1+A4 -> 2 | B5: TN5R | C5: RAYA TUBAN - BADUNG | D5: 357697562 | E5: Tuban | F5: BADUNG | G5: M | H5: 46151 | J5: 46226 | K5: =IFERROR(VLOOKUP(B5,#REF!,4,0),"") | L5: angga | M5: STANDART
A6: =1+A5 -> 3 | B6: TQWG | C6: PC.PC.RAYA TUKAD BADUNG_DPS | D6: 526281234 | E6: Renon | F6: DENPASAR | G6: M | H6: 46167 | K6: =IFERROR(VLOOKUP(B6,#REF!,4,0),"") | L6: pasek | M6: STANDART NEW
A7: =1+A6 -> 4 | B7: TQ2I | C7: PC.CARGO PERMAI 42 - DENPASAR | D7: 552838404 | E7: Ubung | F7: DENPASAR | G7: M | I7: 46179 | K7: =IFERROR(VLOOKUP(B7,#REF!,4,0),"") | L7: pasek | M7: STANDART NEW
A8: =1+A7 -> 5 | B8: FM0K | C8: PC.PC.TIRTA_GIANYAR | D8: 499466205 | E8: Tampaksiring | F8: GIANYAR | G8: Q2 | H8: 46144 | K8: =IFERROR(VLOOKUP(B8,#REF!,4,0),"") | L8: ardian | M8: STANDART NEW
A9: =1+A8 -> 6 | B9: TCK8 | C9: PC.PC.AHMAD YANI - TABANAN | D9: 532214445 | E9: Abian Tuwung | F9: TABANAN | G9: Q2 | H9: 46144 | K9: =IFERROR(VLOOKUP(B9,#REF!,4,0),"") | L9: odi | M9: STANDART NEW
A10: =1+A9 -> 7 | B10: F01U | C10: SUKAWATI - GIANYAR | D10: 565994605 | E10: Sukawati | F10: GIANYAR | G10: Q2 | H10: 46146 | K10: =IFERROR(VLOOKUP(B10,#REF!,4,0),"") | L10: ardian | M10: STANDART
A11: =1+A10 -> 8 | B11: T3AA | C11: TAMPAKSIRING - GIANYAR | D11: 609431063 | E11: Tampaksiring | F11: GIANYAR | G11: Q2 | H11: 46147 | K11: =IFERROR(VLOOKUP(B11,#REF!,4,0),"") | L11: ardian | M11: STANDART NEW
A12: =1+A11 -> 9 | B12: TIAI | C12: PC.ABIANTUWUNG - TBN | D12: 462987147 | E12: Abian Tuwung | F12: TABANAN | G12: Q2 | H12: 46147 | K12: =IFERROR(VLOOKUP(B12,#REF!,4,0),"") | L12: odi | M12: STANDART NEW
A13: =1+A12 -> 10 | B13: FTSN | C13: BLAHKIUH 2 - BADUNG | D13: 489442598 | E13: Blahkiuh | F13: BADUNG | G13: Q2 | H13: 46147 | K13: =IFERROR(VLOOKUP(B13,#REF!,4,0),"") | L13: abdul | M13: STANDART NEW
A14: =1+A13 -> 11 | B14: FG68 | C14: WARIBANG - DPS | D14: 431072320 | E14: Kesiman Petilan | F14: DENPASAR | G14: M | J14: 46210 | K14: =IFERROR(VLOOKUP(B14,#REF!,4,0),"") | L14: bujanga | M14: STANDART
A15: =1+A14 -> 12 | B15: FFD8 | C15: DARMAWANGSA - BADUNG | D15: 489730647 | E15: Benoa | F15: BADUNG | G15: M | H15: 46147 | K15: =IFERROR(VLOOKUP(B15,#REF!,4,0),"") | L15: angga | M15: STANDART
A16: =1+A15 -> 13 | B16: TRI3 | C16: WR. SUPRATMAN 246 - DENPASAR | D16: 400268306 | E16: Kesiman Kertalangu | F16: DENPASAR | G16: M | H16: 46148 | K16: =IFERROR(VLOOKUP(B16,#REF!,4,0),"") | L16: pasek | M16: STANDART
A17: =1+A16 -> 14 | B17: TQ0B | C17: PC.PC.SUNSET ROAD - BADUNG | D17: 464953469 | E17: Legian | F17: BADUNG | G17: M | H17: 46157 | K17: =IFERROR(VLOOKUP(B17,#REF!,4,0),"") | L17: angga | M17: STANDART NEW
A18: =1+A17 -> 15 | B18: THAK | C18: MERDEKA - BANGLI | D18: 351189060 | E18: Bebalang | F18: BANGLI | G18: M | H18: 46160 | I18: 46181 | K18: =IFERROR(VLOOKUP(B18,#REF!,4,0),"") | L18: ardian | M18: STANDART
A19: =1+A18 -> 16 | B19: TEUM | C19: TAMAN BALI - BANGLI | D19: 380643572 | E19: Taman Bali | F19: BANGLI | G19: M | H19: 46160 | K19: =IFERROR(VLOOKUP(B19,#REF!,4,0),"") | L19: ardian | M19: STANDART
A20: =1+A19 -> 17 | B20: T29Q | C20: UNTUNG SUROPATI - SINGARAJA | D20: 526837154 | E20: Banyuning | F20: BULELENG | G20: M | H20: 46170 | I20: 46195 | K20: =IFERROR(VLOOKUP(B20,#REF!,4,0),"") | L20: bisma | M20: STANDART
A21: =1+A20 -> 18 | B21: F9BL | C21: BELIMBING RICE TERRACE TBN | D21: 472744131 | E21: Belimbing | F21: TABANAN | G21: M | H21: 46170 | K21: =IFERROR(VLOOKUP(B21,#REF!,4,0),"") | L21: odi | M21: STANDART NEW
A22: =1+A21 -> 19 | B22: TCUW | C22: MATARAM 2 - BADUNG | D22: 408323810 | E22: Kuta | F22: BADUNG | G22: M | H22: 46172 | K22: =IFERROR(VLOOKUP(B22,#REF!,4,0),"") | L22: angga | M22: STANDART
A23: =1+A22 -> 20 | B23: F6CV | C23: TUKAD IRAWADI NO 47 - DENPASAR | D23: 413754601 | E23: Sesetan | F23: DENPASAR | G23: M | I23: 46193 | K23: =IFERROR(VLOOKUP(B23,#REF!,4,0),"") | L23: pasek | M23: STANDART
A24: =1+A23 -> 21 | B24: FSWE | C24: RAYA TUMBAK BAYUH NO 105 - BADUNG | D24: 421629154 | E24: Tumbak Bayuh | F24: Badung | G24: M | I24: 46203 | K24: =IFERROR(VLOOKUP(B24,#REF!,4,0),"") | L24: abdul | M24: STANDART NEW
A25: =1+A24 -> 22 | B25: FR0E | C25: PADANG KERTA - KARANGASEM | D25: 535662073 | E25: PADANG KERTA | F25: KARANGASEM | G25: M | I25: 46202 | K25: =IFERROR(VLOOKUP(B25,#REF!,4,0),"") | L25: ardian | M25: STANDART NEW
A26: =1+A25 -> 23 | B26: F8CO | C26: GADUNG NO.69 DPS | D26: 373504193 | E26: Sumerta Kauh | F26: DENPASAR | G26: Q2 | H26: 46146 | K26: =IFERROR(VLOOKUP(B26,#REF!,4,0),"") | L26: pasek | M26: STANDART
A27: =1+A26 -> 24 | B27: FATM | C27: ANTAP - TABANAN | D27: 430561213 | E27: Antap | F27: TABANAN | G27: Q2 | H27: 46146 | K27: =IFERROR(VLOOKUP(B27,#REF!,4,0),"") | L27: odi | M27: STANDART
A28: =1+A27 -> 25 | B28: TQ5Q | C28: MEGATI - TABANAN | D28: 384948454 | E28: Megati | F28: TABANAN | G28: Q2 | H28: 46146 | K28: =IFERROR(VLOOKUP(B28,#REF!,4,0),"") | L28: odi | M28: STANDART
A29: =1+A28 -> 26 | B29: TQ76 | C29: AHMAD YANI - SINGARAJA | D29: 450211437 | E29: Kaliuntu | F29: BULELENG | G29: Q2 | H29: 46147 | K29: =IFERROR(VLOOKUP(B29,#REF!,4,0),"") | L29: bisma | M29: STANDART | N29: renove FC (1=14 agt)
A30: =1+A29 -> 27 | B30: TTVV | C30: STP DARMAWANGSA - BADUNG | D30: 442867018 | E30: Benoa | F30: BADUNG | G30: Q2 | H30: 46147 | K30: =IFERROR(VLOOKUP(B30,#REF!,4,0),"") | L30: angga | M30: STANDART
A31: =1+A30 -> 28 | B31: TNHH | C31: TRENGGULI - DENPASAR | D31: 417581219 | E31: Penatih | F31: DENPASAR | G31: Q2 | H31: 46148 | K31: =IFERROR(VLOOKUP(B31,#REF!,4,0),"") | L31: pasek | M31: STANDART
A32: =1+A31 -> 29 | B32: FFYJ | C32: TUKAD PAKERISAN NO.56 _ DPS | D32: 374795313 | E32: Panjer | F32: DENPASAR | G32: Q2 | H32: 46153 | K32: =IFERROR(VLOOKUP(B32,#REF!,4,0),"") | L32: pasek | M32: STANDART
A33: =1+A32 -> 30 | B33: FVDH | C33: AMED VIEW - KARANGASEM | D33: 403241291 | E33: Purwakerti | F33: KARANGASEM | G33: M | K33: =IFERROR(VLOOKUP(B33,#REF!,4,0),"") | L33: ardian | M33: STANDART | N33: TOKO BARU
A34: =1+A33 -> 31 | B34: FKCM | C34: NOJA NO.124_DPS | D34: 444031401 | E34: Kesiman Petilan | F34: DENPASAR | G34: M | J34: 46210 | K34: =IFERROR(VLOOKUP(B34,#REF!,4,0),"") | L34: bujanga | M34: STANDART
A35: =1+A34 -> 32 | B35: FP58 | C35: KEBO IWA - GYR | D35: 367807652 | E35: Blahbatuh | F35: GIANYAR | G35: M | H35: 46168 | J35: 46213 | K35: =IFERROR(VLOOKUP(B35,#REF!,4,0),"") | L35: ardian | M35: STANDART
A36: =1+A35 -> 33 | B36: FORY | C36: TUMBAK BAYUH - BADUNG | D36: 534356805 | E36: Mengwi | F36: BADUNG | G36: M | H36: 46155 | K36: =IFERROR(VLOOKUP(B36,#REF!,4,0),"") | L36: abdul | M36: STANDART
A37: =1+A36 -> 34 | B37: FCCF | C37: PEREAN TENGAH - TABANAN | D37: 440614383 | E37: Perean Tengah | F37: TABANAN | G37: M | I37: 46175 | K37: =IFERROR(VLOOKUP(B37,#REF!,4,0),"") | L37: odi | M37: STANDART
A38: =1+A37 -> 35 | B38: FYOK | C38: WISNU MARGA - TABANAN | D38: 512495496 | E38: Marga | F38: TABANAN | G38: Q2 | H38: 46146 | K38: =IFERROR(VLOOKUP(B38,#REF!,4,0),"") | L38: odi | M38: STANDART
A39: =1+A38 -> 36 | B39: F2MD | C39: HAYAM WURUK NO.185 - DPS | D39: 381062612 | E39: Sumerta Kelod | F39: DENPASAR | G39: Q2 | H39: 46146 | K39: =IFERROR(VLOOKUP(B39,#REF!,4,0),"") | L39: pasek | M39: STANDART
A40: =1+A39 -> 37 | B40: FW28 | C40: NGURAH RAI_KELUNGKUNG | D40: 420453125 | E40: Semarapura Kaja | F40: KLUNGKUNG | G40: Q2 | H40: 46146 | K40: =IFERROR(VLOOKUP(B40,#REF!,4,0),"") | L40: ardian | M40: STANDART
A41: =1+A40 -> 38 | B41: T1M0 | C41: YCG.RATNA NO.20 DPS | D41: 428594425 | E41: Sumerta Kauh | F41: DENPASAR | G41: Q2 | H41: 46146 | K41: =IFERROR(VLOOKUP(B41,#REF!,4,0),"") | L41: pasek | M41: STANDART NEW
...

Sheet Sheet1
A1: NO | B1: kdtk | C1: nama | D1: sal | E1: will | G1: JUL,AGST,SEPT'26 | H1: SO MEI | I1: SO JUNI | J1: SO JULI | K1: SO AGUSTUS | L1: ket | O1: ZONA
R2: SEPTEMBER | S2: 26 | T2: hari kerja
R3: TARGET TOKO SO | S3: 433 | T3: =S3/S2 -> 16.653846
A4: 1 | B4: TFOD | C4: PALGUNA NO 101X-GYR | D4: 385779848 | E4: Ketewel | F4: GIANYAR | G4: M | H4: 46146 | J4: 46204 | L4: ardian | M4: STANDART | R4: PERSONIL | S4: 54 | T4: 17 | U4: =S4/T4 -> 3.1764706
A5: 2 | B5: FAVO | C5: BATU BULAN 2 - GIANYAR | D5: 379980859 | E5: Batu Bulan | F5: GIANYAR | G5: M | H5: 46168 | J5: 46204 | L5: ardian | M5: STANDART
A6: 3 | B6: FTFD | C6: TUKAD BALIAN - DENPASAR | D6: 454992534 | E6: Sidakarya | F6: DENPASAR | G6: M | J6: 46204 | K6: 46260 | M6: STANDART
A7: 4 | B7: FALD | C7: SUKASADA 2 - SINGARAJA | D7: 425467449 | E7: Sukasada | F7: BULELENG | G7: M | J7: 46205 | K7: 46256 | L7: bisma | M7: STANDART
A8: 5 | B8: T4AA | C8: CANGGU - BADUNG | D8: 380991173 | E8: Canggu | F8: BADUNG | G8: M | J8: 46205 | K8: 46254 | L8: abdul | M8: STANDART
A9: 6 | B9: FFXV8 | C9: PC.PC.GUNUNG ATHENA_DPS | D9: 597832289 | E9: Padangsambian Kelod | F9: DENPASAR | G9: M | J9: 46205 | L9: bujanga | M9: STANDART NEW
A10: 7 | B10: FEHU | C10: SPBU LATUSARI 2 - BADUNG | D10: 449120671 | E10: Abiansemal | F10: BADUNG | G10: M | J10: 46206 | K10: 46258 | L10: abdul | M10: STANDART | O10: HITAM
A11: 8 | B11: FFOA | C11: KAYUAMBUA - BANGLI | D11: 460418380 | E11: Tiga | F11: BANGLI | G11: M | H11: 46146 | J11: 46206 | L11: ardian | M11: STANDART
A12: 9 | B12: TKV3 | C12: PC.PC.PECATU - BADUNG | D12: 822519414 | E12: Pecatu | F12: BADUNG | G12: M | H12: 46146 | J12: 46206 | L12: angga | M12: STANDART NEW
A13: 10 | B13: TSAD | C13: PC.PC.DARMAWANGSA 2 - BADUNG | D13: 568566925 | E13: Kutuh | F13: BADUNG | G13: M | J13: 46206 | L13: angga | M13: STANDART NEW
A14: 11 | B14: T0AL | C14: AHMAD YANI - DENPASAR | D14: 569912020 | E14: Peguyangan | F14: DENPASAR | G14: M | J14: 46206 | M14: STANDART NEW
A15: 12 | B15: T0P4 | C15: PC.TAMPAK SIRING 2 - GIANYAR | D15: 528446091 | E15: Manukaya | F15: GIANYAR | G15: M | J15: 46206 | L15: ardian | M15: STANDART NEW
A16: 13 | B16: TLFV | C16: PC.PC.DIPONEGORO_DPS | D16: 538547163 | E16: Pedungan | F16: DENPASAR | G16: M | J16: 46206 | M16: STANDART NEW
A17: 13 | B17: TUKP | C17: PC.PC.TAMAN GRIYA 2 - BADUNG | D17: 603817986 | E17: Jimbaran | F17: BADUNG | G17: M | I17: 46186 | J17: 46207 | K17: 46252 | L17: angga | M17: STANDART NEW | O17: HITAM
A18: 14 | B18: FUZ6 | C18: PULAU MENJANGAN - TABANAN | D18: 516525878 | E18: dauh peken | F18: TABANAN | G18: M | H18: 46167 | J18: 46207 | K18: 46254 | L18: odi | M18: STANDART | O18: HITAM
A19: 15 | B19: FAPA | C19: TEGEH SARI - DENPASAR | D19: 558274600 | E19: Tonja | F19: DENPASAR | G19: M | J19: 46207 | M19: STANDART
A20: 16 | B20: FIJJ | C20: BANJAR ALANGKAJENG - BADUNG | D20: 567084802 | E20: Mengwi | F20: BADUNG | G20: M | J20: 46207 | L20: abdul | M20: STANDART
A21: 17 | B21: TDR0 | C21: RAYA UBUD - GIANYAR | D21: 525936584 | E21: Petulu | F21: GIANYAR | G21: M | I21: 46190 | J21: 46207 | L21: ardian | M21: STANDART NEW
A22: 18 | B22: TR65 | C22: PC.NGURAH RAI - GIANYAR | D22: 529875966 | E22: Gianyar | F22: GIANYAR | G22: M | J22: 46207 | L22: ardian | M22: STANDART NEW
A23: 19 | B23: FIEX | C23: BY PAS NGURAH RAI NO 192-DPS | D23: 385606475 | E23: Sanur Kaja | F23: DENPASAR | G23: M | J23: 46209 | K23: 46252 | M23: STANDART
A24: 20 | B24: TBAJ | C24: YCG.MAYOR METRA - SINGARAJA | D24: 398928385 | E24: Liligundi | F24: BULELENG | G24: M | H24: 46155 | I24: 46192 | J24: 46209 | K24: 46252 | L24: bisma | M24: STANDART NEW
A25: 21 | B25: FZJ7 | C25: SRIKANDI NO .12_SRA | D25: 449343850 | E25: Baktiseraga | F25: BULELENG | G25: M | I25: 46176 | J25: 46209 | K25: 46252 | L25: bisma | M25: STANDART
A26: 22 | B26: T0OP | C26: GRIYA ANYAR - BADUNG | D26: 395146274 | E26: Kuta | F26: BADUNG | G26: M | H26: 46147 | J26: 46209 | K26: 46255 | L26: angga | M26: STANDART
A27: 23 | B27: TQ09 | C27: BUNISARI - BADUNG | D27: 383094118 | E27: Kuta | F27: BADUNG | G27: M | I27: 46190 | J27: 46209 | K27: 46255 | L27: angga | M27: STANDART
A28: 24 | B28: TJ6U | C28: PATIMURA - BADUNG | D28: 353759890 | E28: Kuta | F28: BADUNG | G28: M | J28: 46209 | L28: angga | M28: STANDART
A29: 25 | B29: TMCS | C29: NAKULA 73 - BADUNG | D29: 446521419 | E29: Legian | F29: BADUNG | G29: M | J29: 46209 | K29: 46258 | L29: angga | M29: STANDART
A30: 26 | B30: TA2V | C30: YCG.KEDEWATAN - GIANYAR | D30: 494644561 | E30: Kedewatan | F30: GIANYAR | G30: M | H30: 46171 | J30: 46209 | L30: ardian | M30: STANDART NEW
A31: 27 | B31: FISH | C31: TANAH LOT - TABANAN | D31: 562993067 | E31: Beraban | F31: TABANAN | G31: M | H31: 46158 | I31: 46186 | J31: 46209 | L31: odi | M31: STANDART
A32: 28 | B32: FSE5 | C32: CEPAKA - TABANAN | D32: 482362439 | E32: Cepaka | F32: TABANAN | G32: M | J32: 46209 | L32: odi | M32: STANDART
A33: 29 | B33: FAOG | C33: PC.RAYA SEMPIDI - BDG | D33: 527678304 | E33: Sempidi | F33: BADUNG | G33: M | J33: 46209 | L33: abdul | M33: STANDART NEW
A34: 30 | B34: F44K | C34: GUNUNG RINJANI - DENPASAR | D34: 457374457 | E34: Pemecutan Kelod | F34: DENPASAR | G34: M | H34: 46151 | I34: 46185 | J34: 46210 | K34: 46253 | L34: pasek | M34: STANDART | O34: HITAM
A35: 31 | B35: T4AL | C35: PULAU SAELUS - DENPASAR | D35: 387219325 | E35: Sesetan | F35: DENPASAR | G35: M | J35: 46210 | K35: 46253 | M35: STANDART
A36: 32 | B36: TMXX | C36: DEWI SRI LEGIAN - BADUNG | D36: 342167641 | E36: Kuta | F36: BADUNG | G36: M | J36: 46210 | L36: angga | M36: STANDART
A37: 33 | B37: TESF | C37: YCG.KAMPUS UNUD 3 - BADUNG | D37: 440062293 | E37: Jimbaran | F37: BADUNG | G37: M | J37: 46210 | K37: 46253 | L37: angga | M37: STANDART NEW
A38: 34 | B38: FV3G | C38: BATU BOLONG 12 - BADUNG | D38: 544864972 | E38: Canggu | F38: BADUNG | G38: M | H38: 46149 | I38: 46192 | J38: 46210 | K38: 46254 | L38: abdul | M38: STANDART | O38: HITAM
A39: 35 | B39: TSAP | C39: BONDALEM - SINGARAJA | D39: #N/A | E39: Bondalem | F39: BULELENG | G39: M | H39: 46162 | J39: 46210 | L39: bisma | M39: STANDART | O39: renove FC (1=28 agst)
A40: 36 | B40: F31B | C40: RAYA KINTAMANI 602 - BANGLI | D40: 523721408 | E40: Kintamani | F40: BANGLI | G40: M | H40: 46170 | I40: 46198 | J40: 46210 | L40: ardian | M40: STANDART
...

Sheet Sheet4
A1: NAMA | B1: (All)
A3: Count of NAMA
A4: KORLAP | B4: Total
A5: ABDUL RAHMAN | B5: 10 | C5: 3
A6: ANGGA ARDIYANSYAH | B6: 9 | C6: 3
A7: I GEDE PASEK SANTIKA | B7: 10 | C7: 3
A8: I WAYAN ANGGA RISTA | B8: 9 | C8: 3
A9: ODI TRI ANGGARA | B9: 9 | C9: 3
A10: PUTU BISMA | B10: 8 | C10: 3
A11: Grand Total | B11: 55

Sheet PERSONIL
A1: NIK | B1: NAMA | C1: NIK | D1: KOORDINATOR | E1: NIK | F1: KORLAP | G1: NO HP | H1: DOMISILI | K1: PROYEKSI SEPTEMBER
A2: 2015478551 | B2: ATHILA HARVE SEPTANANDO | C2: 2013182311 | D2: YOGI SEPTA ARIF PRATAMA | E2: 2013180506 | F2: I WAYAN ANGGA RISTA | K2: KETERANGAN | L2: ABDUL RAHMAN | M2: ANGGA ARDIYANSYAH | N2: I GEDE PASEK SANTIKA | O2: I WAYAN ANGGA RISTA | P2: ODI TRI ANGGARA | Q2: PUTU BISMA | R2: TOTAL
A3: 2015733322 | B3: ABIL YAHYA ASSYADILI | C3: 2013182311 | D3: YOGI SEPTA ARIF PRATAMA | E3: 2013180506 | F3: I WAYAN ANGGA RISTA | K3: Personil | L3: 9 | M3: 9 | N3: 10 | O3: 10 | P3: 9 | Q3: 8 | R3: =SUM(L3:Q3) -> 55
A4: 2015644524 | B4: WAHYU SULISTYO NUR ADI | C4: 2013182311 | D4: YOGI SEPTA ARIF PRATAMA | E4: 2013180506 | F4: I WAYAN ANGGA RISTA | K4: Reguler | L4: 3 | M4: 3 | N4: 3 | O4: 3 | P4: 3 | Q4: 2 | R4: =SUM(L4:Q4) -> 17
A5: 2013182311 | B5: YOGI SEPTA ARIF PRATAMA | C5: 2013182311 | D5: YOGI SEPTA ARIF PRATAMA | E5: 2013180506 | F5: I WAYAN ANGGA RISTA | K5: Cluster | L5: 1 | M5: 1 | N5: 1 | O5: 1 | P5: 1 | Q5: 1 | R5: =SUM(L5:Q5) -> 6
A6: 2015478550 | B6: AGUSTINUS SAFRUDIN | C6: 2015100909 | D6: CAHYO PRASETYO UTOMO | E6: 2013180506 | F6: I WAYAN ANGGA RISTA
A7: 2015742253 | B7: JULIO BOY NENOTEK | C7: 2015100909 | D7: CAHYO PRASETYO UTOMO | E7: 2013180506 | F7: I WAYAN ANGGA RISTA
A8: 2015762238 | B8: SYAHRUL HANAFI | C8: 2015100909 | D8: CAHYO PRASETYO UTOMO | E8: 2013180506 | F8: I WAYAN ANGGA RISTA
A9: 2015100909 | B9: CAHYO PRASETYO UTOMO | C9: 2015100909 | D9: CAHYO PRASETYO UTOMO | E9: 2013180506 | F9: I WAYAN ANGGA RISTA
A10: 2013180506 | B10: I WAYAN ANGGA RISTA | C10: 2013180506 | D10: I WAYAN ANGGA RISTA | E10: 2013180506 | F10: I WAYAN ANGGA RISTA | G10: 085237036614 | H10: BATUBULAN,SUKAWATI,GIANYAR
A11: 2015632428 | B11: JOVAN FALAH MAULANA | C11: 2015154121 | D11: MUHAMMAD BAGUS MAULANA | E11: 2013060277 | F11: ODI TRI ANGGARA
A12: 2015675462 | B12: FEBRI DWI PRATAMA | C12: 2015154121 | D12: MUHAMMAD BAGUS MAULANA | E12: 2013060277 | F12: ODI TRI ANGGARA
A13: 2015362961 | B13: KETUT SATRIA DINATA | C13: 2015154121 | D13: MUHAMMAD BAGUS MAULANA | E13: 2013060277 | F13: ODI TRI ANGGARA
A14: 2015154121 | B14: MUHAMMAD BAGUS MAULANA | C14: 2015154121 | D14: MUHAMMAD BAGUS MAULANA | E14: 2013060277 | F14: ODI TRI ANGGARA
A15: 2015471984 | B15: I GUSTI NGURAH KRISNA PUTRA | C15: 2015060270 | D15: I MADE RUDIARTA | E15: 2013060277 | F15: ODI TRI ANGGARA
A16: 2015742254 | B16: I KETUT KRISNATA | C16: 2015060270 | D16: I MADE RUDIARTA | E16: 2013060277 | F16: ODI TRI ANGGARA
A17: 2015747088 | B17: I PUTU AGUNG FEBRIANTO | C17: 2015060270 | D17: I MADE RUDIARTA | E17: 2013060277 | F17: ODI TRI ANGGARA | G17: 082146310498 | H17: TABANAN
A18: 2015060270 | B18: I MADE RUDIARTA | C18: 2015060270 | D18: I MADE RUDIARTA | E18: 2013060277 | F18: ODI TRI ANGGARA
A19: 2013060277 | B19: ODI TRI ANGGARA | C19: 2013060277 | D19: ODI TRI ANGGARA | E19: 2013060277 | F19: ODI TRI ANGGARA
A20: 2015408869 | B20: SAEPUL BAHRI | C20: 2015302836 | D20: RAFLI SALMAN ADITYA | E20: 2013090888 | F20: ANGGA ARDIYANSYAH | G20: 085339461696 | H20: Pemogan, Denpasar
A21: 2015161965 | B21: ANTON TRI SUCITRO | C21: 2015302836 | D21: RAFLI SALMAN ADITYA | E21: 2013090888 | F21: ANGGA ARDIYANSYAH | G21: 085946630374 | H21: Gianyar kota
A22: 2015644525 | B22: SUBHAN MAULANA ISHAQ | C22: 2015302836 | D22: RAFLI SALMAN ADITYA | E22: 2013090888 | F22: ANGGA ARDIYANSYAH | G22: - | H22: Badung
A23: 2015302836 | B23: RAFLI SALMAN ADITYA | C23: 2015302836 | D23: RAFLI SALMAN ADITYA | E23: 2013090888 | F23: ANGGA ARDIYANSYAH | G23: 081236412656 | H23: Klungkung/Semarapura
A24: 2015467115 | B24: MUHAMMAD GUFRON | C24: 2015377937 | D24: IKADEK GALANG SURYA DARMA | E24: 2013090888 | F24: ANGGA ARDIYANSYAH | G24: 085338524874 | H24: Buruan, GIANYAR
A25: 2015583887 | B25: FIKI SANDHIKA PUTRA | C25: 2015377937 | D25: IKADEK GALANG SURYA DARMA | E25: 2013090888 | F25: ANGGA ARDIYANSYAH | G25: 081333633259 | H25: BONA , GIANYAR
A26: 2015655271 | B26: MARCHEL BAGAS | C26: 2015377937 | D26: IKADEK GALANG SURYA DARMA | E26: 2013090888 | F26: ANGGA ARDIYANSYAH | G26: 081231925070 | H26: UBUD,GIANYAR
A27: 2015377937 | B27: IKADEK GALANG SURYA DARMA | C27: 2015377937 | D27: IKADEK GALANG SURYA DARMA | E27: 2013090888 | F27: ANGGA ARDIYANSYAH
A28: 2013090888 | B28: ANGGA ARDIYANSYAH | C28: 2013090888 | D28: ANGGA ARDIYANSYAH | E28: 2013090888 | F28: ANGGA ARDIYANSYAH | G28: 08814881377 | H28: Gianyar
A29: 2015503577 | B29: AHMAD RYOS AJI HERLIAN | C29: 2015170503 | D29: I GEDE JULIANTO | E29: 2013159827 | F29: ABDUL RAHMAN | G29: 085706420856 | H29: DENPASAR KOTA
A30: 2015640856 | B30: RISKI BAYU RAMADHAN | C30: 2015170503 | D30: I GEDE JULIANTO | E30: 2013159827 | F30: ABDUL RAHMAN | G30: 085954756545 | H30: DENPASAR KOTA
A31: 2015731683 | B31: DWI CAHYA PUTRA | C31: 2015170503 | D31: I GEDE JULIANTO | E31: 2013159827 | F31: ABDUL RAHMAN | G31: 081216520079 | H31: RENON, DENPASAR
A32: 2015748049 | B32: MOCH FAHRUL ROSI | C32: 2015170503 | D32: I GEDE JULIANTO | E32: 2013159827 | F32: ABDUL RAHMAN | G32: 081455045238 | H32: UBUD GIANYAR
A33: 2015170503 | B33: I GEDE JULIANTO | C33: 2015170503 | D33: I GEDE JULIANTO | E33: 2013159827 | F33: ABDUL RAHMAN
A34: 2015497215 | B34: LALU FARA AZIS | C34: 2015178874 | D34: AHMAD BAGUS AKBAR | E34: 2013159827 | F34: ABDUL RAHMAN | G34: 081917777374 | H34: DENPASAR KOTA
A35: 2015496206 | B35: I GEDE AGUS BUDI SUARNATA | C35: 2015178874 | D35: AHMAD BAGUS AKBAR | E35: 2013159827 | F35: ABDUL RAHMAN | G35: 081936790481 | H35: TUKAD PETANU , DENPASAR
A36: 2015743981 | B36: I PUTU AGUS PUTRA WIJAYA | C36: 2015178874 | D36: AHMAD BAGUS AKBAR | E36: 2013159827 | F36: ABDUL RAHMAN
A37: 2015178874 | B37: AHMAD BAGUS AKBAR | C37: 2015178874 | D37: AHMAD BAGUS AKBAR | E37: 2013159827 | F37: ABDUL RAHMAN | G37: 085857839034 | H37: TABANAN
A38: 2013159827 | B38: ABDUL RAHMAN | C38: 2013159827 | D38: ABDUL RAHMAN | E38: 2013159827 | F38: ABDUL RAHMAN | G38: 085738982274 | H38: GIANYAR ,KOTA
A39: 2015552796 | B39: ADAM FAJAR RAMADHAN | C39: 2015082091 | D39: AGUNG DWI SETIAWAN | E39: 2013217571 | F39: I GEDE PASEK SANTIKA | G39: 0895422644281 | H39: Tukad Citarum, Denpasar
A40: 2015709471 | B40: FANI SULISTIYO | C40: 2015082091 | D40: AGUNG DWI SETIAWAN | E40: 2013217571 | F40: I GEDE PASEK SANTIKA | G40: 089520421287 | H40: A.Yani Utara, Denpasar
...

Sheet MASTER TOKO BALI
A1: NO | B1: KDTK | C1: NAMA | D1: KOORDINAT | E1: SALDO TOKO AGUSTUS | F1: KAS TOKO | G1: AM | H1: AS | I1: WILAYAH | J1: KABUPATEN | K1: KECAMATAN | L1: COVERAGE | M1: Type SO | N1: SO MEI '26 | O1: SO JUNI '26 | P1: SO JULI '26 | Q1: SO AGUSTUS '26 | R1: SO SEPTEMBER '26 | S1: FREKUENSI TIDAK SO | T1: RENTANG HARI SO | U1: KETERANGAN | V1: ZONA | W1: SO AKTIVA | X1: KORLAP | AE1: RENCANA SO BULAN SEPTEMBER 2026
A2: 1 | B2: F02X | C2: IMAM BONJOL - DENPASAR | D2: S8 66 59.96 E115 20 66.90 | E2: 479482772 | F2: 2500000 | G2: THJ | H2: DOM | I2: BALI | J2: DENPASAR | K2: =VLOOKUP($B2,'WILL TOKO SEP'!A3:AK742,37,0) -> DENPASAR BARAT | L2: DC | M2: M | N2: 46158 | O2: 46184 | P2: 46213 | Q2: 46248 | R2: =IFERROR(VLOOKUP($B2,JADWAL!$G$6:$J$690,4,0),"") -> 46267 | S2: =COUNTIF(N2:P2,"0") -> 0 | U2: TOKO EKSIS | V2: ZONA HITAM | X2: #N/A | Z2: SEPTEMBER | AA2: 26 | AB2: hari kerja | AE2: KORLAP | AF2: PERSONIL PER KORLAP | AG2: REGULAR | AH2: EXTRA | AI2: TOTAL | AJ2: SEMINGGU 4 KALI | AK2: EXTRA SEPTEMBER
A3: =A2+1 -> 2 | B3: F08C | C3: KEBO IWA - DENPASAR | D3: S8 38 04.7 E115 11 04.0 | E3: 507586793 | F3: 3500000 | G3: THR | H3: BAS | I3: BALI | J3: DENPASAR | K3: =VLOOKUP($B3,'WILL TOKO SEP'!A4:AK743,37,0) -> DENPASAR BARAT | L3: DC | M3: M | N3: 46147 | O3: 0 | P3: 46234 | Q3: 0 | R3: =IFERROR(VLOOKUP($B3,JADWAL!$G$6:$J$690,4,0),"") -> 46268 | S3: =COUNTIF(N3:P3,"0") -> 1 | U3: TOKO EKSIS | V3: NON ZONA HITAM | X3: 0 | Z3: TARGET TOKO SO | AA3: 433 | AB3: =AA3/AA2 -> 16.653846 | AE3: ABDUL RAHMAN | AF3: 10 | AG3: 3 | AH3: 2 | AI3: =AG3+AH3 -> 5 | AJ3: =AI3*4 -> 20
A4: =A3+1 -> 3 | B4: F0L0 | C4: BANTAS - TABANAN | D4: S8 30 06.8 E115 03 46.2 | E4: 689951930 | F4: 4500000 | G4: JPT | H4: INP | I4: BALI | J4: TABANAN | K4: =VLOOKUP($B4,'WILL TOKO SEP'!A5:AK744,37,0) -> SELEMADEG TIMUR | L4: DC | M4: M | N4: 0 | O4: 0 | P4: 46214 | Q4: 0 | R4: =IFERROR(VLOOKUP($B4,JADWAL!$G$6:$J$690,4,0),"") | S4: =COUNTIF(N4:P4,"0") -> 2 | U4: TOKO EKSIS | V4: NON ZONA HITAM | X4: odi | Z4: PERSONIL | AA4: 55 | AB4: 17 | AC4: =AA4/AB4 -> 3.2352941 | AE4: ANGGA ARDIYANSYAH | AF4: 9 | AG4: 3 | AH4: 2 | AI4: =AG4+AH4 -> 5 | AJ4: =AI4*4 -> 20
A5: =A4+1 -> 4 | B5: F0PT | C5: PC.PC.RAYA LODTUNDUH | D5: 8°32'52.92"S 115°15'42.85"E | E5: 552870410 | F5: 3000000 | G5: ATN | H5: MRS | I5: BALI | J5: GIANYAR | K5: =VLOOKUP($B5,'WILL TOKO SEP'!A6:AK745,37,0) -> UBUD | L5: IGR | M5: M | N5: 0 | O5: 0 | P5: 46223 | Q5: 0 | R5: =IFERROR(VLOOKUP($B5,JADWAL!$G$6:$J$690,4,0),"") | S5: =COUNTIF(N5:P5,"0") -> 2 | U5: TOKO EKSIS | V5: NON ZONA HITAM | X5: ardian | AE5: I GEDE PASEK SANTIKA | AF5: 10 | AG5: 3 | AH5: 2 | AI5: =AG5+AH5 -> 5 | AJ5: =AI5*4 -> 20
A6: =A5+1 -> 5 | B6: F17R | C6: TEGES - DENPASAR | D6: S8 39 28.4 E115 10 53.7 | E6: 422371082 | F6: 3000000 | G6: THR | H6: WWD | I6: BALI | J6: DENPASAR | K6: =VLOOKUP($B6,'WILL TOKO SEP'!A7:AK746,37,0) -> DENPASAR BARAT | L6: DC | M6: M | N6: 0 | O6: 46178 | P6: 46231 | Q6: 0 | R6: =IFERROR(VLOOKUP($B6,JADWAL!$G$6:$J$690,4,0),"") | S6: =COUNTIF(N6:P6,"0") -> 1 | U6: TOKO EKSIS | V6: NON ZONA HITAM | X6: 0 | AE6: I WAYAN ANGGA RISTA | AF6: 9 | AG6: 3 | AH6: 2 | AI6: =AG6+AH6 -> 5 | AJ6: =AI6*4 -> 20
A7: =A6+1 -> 6 | B7: F1HT | C7: TAMAN GIRI NO .77 BDG | D7: 8°47'34.07"S 115°11'41.00"E | E7: 462389795 | F7: 2500000 | G7: MIL | H7: REN | I7: BALI | J7: BADUNG | K7: =VLOOKUP($B7,'WILL TOKO SEP'!A8:AK747,37,0) -> KUTA SELATAN | L7: IGR | M7: M | N7: 0 | O7: 46178 | P7: 0 | Q7: 46261 | R7: =IFERROR(VLOOKUP($B7,JADWAL!$G$6:$J$690,4,0),"") -> 46268 | S7: =COUNTIF(N7:P7,"0") -> 2 | U7: TOKO EKSIS | V7: NON ZONA HITAM | X7: angga | AE7: ODI TRI ANGGARA | AF7: 9 | AG7: 3 | AH7: 2 | AI7: =AG7+AH7 -> 5 | AJ7: =AI7*4 -> 20
A8: =A7+1 -> 7 | B8: F1RC | C8: RAYA MUNGGU_BDG | D8: 8°36'7.22"S 115° 9'33.97"E | E8: 440733471 | F8: 2000000 | G8: LAO | H8: SAM | I8: BALI | J8: BADUNG | K8: =VLOOKUP($B8,'WILL TOKO SEP'!A9:AK748,37,0) -> MENGWI | L8: DC | M8: M | N8: 46165 | O8: 46190 | P8: 46212 | Q8: 46241 | R8: =IFERROR(VLOOKUP($B8,JADWAL!$G$6:$J$690,4,0),"") | S8: =COUNTIF(N8:P8,"0") -> 0 | U8: TOKO EKSIS | V8: NON ZONA HITAM | X8: #N/A | AE8: PUTU BISMA | AF8: 8 | AG8: 2 | AH8: 1 | AI8: =AG8+AH8 -> 3 | AJ8: =AI8*4 -> 12
A9: =A8+1 -> 8 | B9: F1RX | C9: RAYA GAJAH MADA - SINGARAJA | D9: S8 6 35.40 E115 5 28.67 | E9: 392239030 | F9: 2000000 | G9: APA | H9: AMN | I9: BALI | J9: BULELENG | K9: =VLOOKUP($B9,'WILL TOKO SEP'!A10:AK749,37,0) -> BULELENG | L9: DC | M9: M | N9: 46147 | O9: 46197 | P9: 46219 | Q9: 46245 | R9: =IFERROR(VLOOKUP($B9,JADWAL!$G$6:$J$690,4,0),"") | S9: =COUNTIF(N9:P9,"0") -> 0 | U9: TOKO EKSIS | V9: NON ZONA HITAM | X9: #N/A | AG9: =SUM(AG3:AG8) -> 17 | AH9: =SUM(AH3:AH8) -> 11 | AI9: =AG9+AH9 -> 28 | AJ9: =AI9*4 -> 112 | AK9: =AJ9*4 -> 448
A10: =A9+1 -> 9 | B10: F2BK | C10: PC.CIUNGWANARA - GIANYAR | D10: S8 32 13.3 E115 19 23.1 | E10: 506541486 | F10: 4000000 | G10: ATN | H10: MKH | I10: BALI | J10: GIANYAR | K10: =VLOOKUP($B10,'WILL TOKO SEP'!A11:AK750,37,0) -> GIANYAR | L10: IGR | M10: M | N10: 0 | O10: 46193 | P10: 0 | Q10: 0 | R10: =IFERROR(VLOOKUP($B10,JADWAL!$G$6:$J$690,4,0),"") | S10: =COUNTIF(N10:P10,"0") -> 2 | U10: TOKO EKSIS | V10: NON ZONA HITAM | X10: ardian
A11: =A10+1 -> 10 | B11: F2G2 | C11: GUNUNG SANGHYANG 227 BADUNG | D11: S8 38 48.00 E11510 30.30 | E11: 438845947 | F11: 2000000 | G11: THR | H11: WWD | I11: BALI | J11: BADUNG | K11: =VLOOKUP($B11,'WILL TOKO SEP'!A12:AK751,37,0) -> KUTA UTARA | L11: DC | M11: M | N11: 46158 | O11: 46188 | P11: 46224 | Q11: 46240 | R11: =IFERROR(VLOOKUP($B11,JADWAL!$G$6:$J$690,4,0),"") -> 46269 | S11: =COUNTIF(N11:P11,"0") -> 0 | U11: TOKO EKSIS | V11: ZONA HITAM | X11: #N/A
A12: =A11+1 -> 11 | B12: F2MV | C12: JEPUN_BADUNG | D12: 8°47'44.24"S 115° 8'56.29"E | E12: 472475414 | F12: 2000000 | G12: MIL | H12: DDY | I12: BALI | J12: BADUNG | K12: =VLOOKUP($B12,'WILL TOKO SEP'!A13:AK752,37,0) -> KUTA SELATAN | L12: DC | M12: M | N12: 46164 | O12: 0 | P12: 46213 | Q12: 0 | R12: =IFERROR(VLOOKUP($B12,JADWAL!$G$6:$J$690,4,0),"") | S12: =COUNTIF(N12:P12,"0") -> 1 | U12: TOKO EKSIS | V12: NON ZONA HITAM | X12: angga
A13: =A12+1 -> 12 | B13: F2QU | C13: DIPONEGORO - TABANAN | D13: S8 31 59.3 E115 08 01.0 | E13: 396855644 | F13: 2500000 | G13: JPT | H13: SFH | I13: BALI | J13: TABANAN | K13: =VLOOKUP($B13,'WILL TOKO SEP'!A14:AK753,37,0) -> TABANAN | L13: DC | M13: M | N13: 0 | O13: 46182 | P13: 0 | Q13: 46239 | R13: =IFERROR(VLOOKUP($B13,JADWAL!$G$6:$J$690,4,0),"") | S13: =COUNTIF(N13:P13,"0") -> 2 | U13: TOKO EKSIS | V13: NON ZONA HITAM | X13: #N/A
A14: =A13+1 -> 13 | B14: F31B | C14: RAYA KINTAMANI 602 - BANGLI | D14: S8 14 57.96 E11519 45.16 | E14: 502637434 | F14: 2000000 | G14: JUN | H14: IKN | I14: BALI | J14: BANGLI | K14: =VLOOKUP($B14,'WILL TOKO SEP'!A15:AK754,37,0) -> KINTAMANI | L14: DC | M14: M | N14: 46170 | O14: 46198 | P14: 46210 | Q14: 0 | R14: =IFERROR(VLOOKUP($B14,JADWAL!$G$6:$J$690,4,0),"") | S14: =COUNTIF(N14:P14,"0") -> 0 | U14: TOKO EKSIS | V14: NON ZONA HITAM | X14: ardian
A15: =A14+1 -> 14 | B15: F34V | C15: RAYA BATURITI - TABANAN | D15: S08 18 24.86 E115 10 41.77 | E15: 439478960 | F15: 2000000 | G15: LAO | H15: KAR | I15: BALI | J15: TABANAN | K15: =VLOOKUP($B15,'WILL TOKO SEP'!A16:AK755,37,0) -> BATURITI | L15: DC | M15: M | N15: 46149 | O15: 46203 | P15: 46216 | Q15: 0 | R15: =IFERROR(VLOOKUP($B15,JADWAL!$G$6:$J$690,4,0),"") -> 46267 | S15: =COUNTIF(N15:P15,"0") -> 0 | U15: TOKO EKSIS | V15: NON ZONA HITAM | X15: odi
A16: =A15+1 -> 15 | B16: F37V | C16: JAGARAGA_GYR | D16: 8°35'40.29"S 115°16'9.49"E | E16: 380513165 | F16: 2000000 | G16: ATN | H16: MRS | I16: BALI | J16: GIANYAR | K16: =VLOOKUP($B16,'WILL TOKO SEP'!A17:AK756,37,0) -> SUKAWATI | L16: IGR | M16: M | N16: 0 | O16: 46198 | P16: 46224 | Q16: 0 | R16: =IFERROR(VLOOKUP($B16,JADWAL!$G$6:$J$690,4,0),"") | S16: =COUNTIF(N16:P16,"0") -> 1 | U16: TOKO EKSIS | V16: NON ZONA HITAM | X16: ardian
A17: =A16+1 -> 16 | B17: F3QQ | C17: PULAU TARAKAN - DENPASAR | D17: S8 40 36.7 E115 12 35.0 | E17: 375174949 | F17: 2000000 | G17: THJ | H17: DOM | I17: BALI | J17: DENPASAR | K17: =VLOOKUP($B17,'WILL TOKO SEP'!A18:AK757,37,0) -> DENPASAR BARAT | L17: DC | M17: M | N17: 46167 | O17: 46192 | P17: 46212 | Q17: 46239 | R17: =IFERROR(VLOOKUP($B17,JADWAL!$G$6:$J$690,4,0),"") -> 46267 | S17: =COUNTIF(N17:P17,"0") -> 0 | U17: TOKO EKSIS | V17: ZONA HITAM | X17: #N/A
A18: =A17+1 -> 17 | B18: F3XG | C18: LEMBU SORA - DENPASAR | D18: S8 37 11.4 E115 12 15.1 | E18: 381696271 | F18: 2500000 | G18: DTO | H18: IHN | I18: BALI | J18: DENPASAR | K18: =VLOOKUP($B18,'WILL TOKO SEP'!A19:AK758,37,0) -> DENPASAR UTARA | L18: DC | M18: M | N18: 46170 | O18: 0 | P18: 46231 | Q18: 46247 | R18: =IFERROR(VLOOKUP($B18,JADWAL!$G$6:$J$690,4,0),"") | S18: =COUNTIF(N18:P18,"0") -> 1 | U18: TOKO EKSIS | V18: NON ZONA HITAM | X18: #N/A
A19: =A18+1 -> 18 | B19: F4C8 | C19: PC.PC.HIKING G.BATUR | D19: S8 15 1.36 115 23 50.67 | E19: 641945341 | F19: 3500000 | G19: JUN | H19: MRZ | I19: BALI | J19: BANGLI | K19: =VLOOKUP($B19,'WILL TOKO SEP'!A20:AK759,37,0) -> KINTAMANI | L19: DC | M19: M | N19: 46162 | O19: 46196 | P19: 0 | Q19: 0 | R19: =IFERROR(VLOOKUP($B19,JADWAL!$G$6:$J$690,4,0),"") -> 46268 | S19: =COUNTIF(N19:P19,"0") -> 1 | U19: TOKO EKSIS | V19: NON ZONA HITAM | X19: ardian
A20: =A19+1 -> 19 | B20: F4SD | C20: SPBU GATOT SUBROTO TIMUR DPS | D20: S8 38 08.9 E115 14 15.5 | E20: 366862051 | F20: 2000000 | G20: SKI | H20: KDI | I20: BALI | J20: DENPASAR | K20: =VLOOKUP($B20,'WILL TOKO SEP'!A21:AK760,37,0) -> DENPASAR TIMUR | L20: IGR | M20: M | N20: 0 | O20: 0 | P20: 46211 | Q20: 0 | R20: =IFERROR(VLOOKUP($B20,JADWAL!$G$6:$J$690,4,0),"") -> 46270 | S20: =COUNTIF(N20:P20,"0") -> 2 | U20: TOKO EKSIS | V20: NON ZONA HITAM | X20: bujanga
A21: =A20+1 -> 20 | B21: F4UG | C21: YCG.BY PAS IDA BAGUS MANTRA NO.119 | D21: 8°34'4.26"S 115°22'46.76"E | E21: 503960218 | F21: 2500000 | G21: JUN | H21: IDA | I21: BALI | J21: KLUNGKUNG | K21: =VLOOKUP($B21,'WILL TOKO SEP'!A22:AK761,37,0) -> BANJARANGKAN | L21: DC | M21: M | N21: 46150 | O21: 0 | P21: 46227 | Q21: 0 | R21: =IFERROR(VLOOKUP($B21,JADWAL!$G$6:$J$690,4,0),"") | S21: =COUNTIF(N21:P21,"0") -> 1 | U21: TOKO EKSIS | V21: NON ZONA HITAM | X21: ardian
A22: =A21+1 -> 21 | B22: F55L | C22: NEGARA - JEMBRANA | D22: S8 21 38.2 E114 37 26.8 | E22: 504199320 | F22: 2500000 | G22: SKI | H22: EKS | I22: BALI | J22: JEMBRANA | K22: =VLOOKUP($B22,'WILL TOKO SEP'!A23:AK762,37,0) -> #N/A | L22: DC | M22: M | N22: 46163 | O22: 46197 | P22: 46228 | Q22: 0 | R22: =IFERROR(VLOOKUP($B22,JADWAL!$G$6:$J$690,4,0),"") | S22: =COUNTIF(N22:P22,"0") -> 0 | U22: TOKO EKSIS | V22: NON ZONA HITAM | X22: odi
A23: =A22+1 -> 22 | B23: F5NN | C23: TUAKILANG - TABANAN | D23: S8 30 52.6 E115 07 50.8 | E23: 523170045 | F23: 3500000 | G23: JPT | H23: STN | I23: BALI | J23: TABANAN | K23: =VLOOKUP($B23,'WILL TOKO SEP'!A24:AK763,37,0) -> TABANAN | L23: DC | M23: M | N23: 46147 | O23: 0 | P23: 46223 | Q23: 0 | R23: =IFERROR(VLOOKUP($B23,JADWAL!$G$6:$J$690,4,0),"") | S23: =COUNTIF(N23:P23,"0") -> 1 | U23: TOKO EKSIS | V23: NON ZONA HITAM | X23: odi
A24: =A23+1 -> 23 | B24: F68A | C24: GILIMANUK - JEMBRANA | D24: S8 10 16.1 E114 26 08.7 | E24: 579041855 | F24: 4500000 | G24: SKI | H24: EKS | I24: BALI | J24: JEMBRANA | K24: =VLOOKUP($B24,'WILL TOKO SEP'!A25:AK764,37,0) -> #N/A | L24: DC | M24: M | N24: 46165 | O24: 0 | P24: 46225 | Q24: 46260 | R24: =IFERROR(VLOOKUP($B24,JADWAL!$G$6:$J$690,4,0),"") | S24: =COUNTIF(N24:P24,"0") -> 1 | U24: TOKO EKSIS | V24: NON ZONA HITAM | X24: odi
A25: =A24+1 -> 24 | B25: F6CV | C25: TUKAD IRAWADI NO 47 - DENPASAR | D25: S8 41 1.87 E115 13 17.62 | E25: 397294873 | F25: 2000000 | G25: DTO | H25: ANT | I25: BALI | J25: DENPASAR | K25: =VLOOKUP($B25,'WILL TOKO SEP'!A26:AK765,37,0) -> DENPASAR SELATAN | L25: IGR | M25: M | N25: 0 | O25: 46193 | P25: 0 | Q25: 46237 | R25: =IFERROR(VLOOKUP($B25,JADWAL!$G$6:$J$690,4,0),"") | S25: =COUNTIF(N25:P25,"0") -> 2 | U25: TOKO EKSIS | V25: NON ZONA HITAM | X25: #N/A
A26: =A25+1 -> 25 | B26: F6KP | C26: ANTASURA 60 - DENPASAR | D26: S8 36 59.9 E115 13 22.0 | E26: 457856762 | F26: 2000000 | G26: DTO | H26: IHN | I26: BALI | J26: DENPASAR | K26: =VLOOKUP($B26,'WILL TOKO SEP'!A27:AK766,37,0) -> DENPASAR UTARA | L26: DC | M26: M | N26: 46153 | O26: 46188 | P26: 46223 | Q26: 46245 | R26: =IFERROR(VLOOKUP($B26,JADWAL!$G$6:$J$690,4,0),"") | S26: =COUNTIF(N26:P26,"0") -> 0 | U26: TOKO EKSIS | V26: ZONA HITAM | X26: #N/A
A27: =A26+1 -> 26 | B27: F7PV | C27: SERIRIT KM 6 -SRA | D27: 8° 8'38.18"S 115° 3'2.63"E | E27: 463142088 | F27: 3000000 | G27: APA | H27: IBN | I27: BALI | J27: BULELENG | K27: =VLOOKUP($B27,'WILL TOKO SEP'!A28:AK767,37,0) -> BULELENG | L27: DC | M27: M | N27: 46148 | O27: 0 | P27: 46233 | Q27: 0 | R27: =IFERROR(VLOOKUP($B27,JADWAL!$G$6:$J$690,4,0),"") | S27: =COUNTIF(N27:P27,"0") -> 1 | U27: TOKO EKSIS | V27: NON ZONA HITAM | X27: bisma
A28: =A27+1 -> 27 | B28: F7Q6 | C28: BUANA PERMATA HIJAU - DPS | D28: 8°39'36.99"S 115°11'25.46"E | E28: 434381683 | F28: 2000000 | G28: THR | H28: WWD | I28: BALI | J28: DENPASAR | K28: =VLOOKUP($B28,'WILL TOKO SEP'!A29:AK768,37,0) -> DENPASAR BARAT | L28: DC | M28: M | N28: 46161 | O28: 46185 | P28: 46213 | Q28: 46247 | R28: =IFERROR(VLOOKUP($B28,JADWAL!$G$6:$J$690,4,0),"") | S28: =COUNTIF(N28:P28,"0") -> 0 | U28: TOKO EKSIS | V28: ZONA HITAM | X28: #N/A
A29: =A28+1 -> 28 | B29: F7W8 | C29: PC.RAYA LUWUS TBN | D29: 8°24'25.72"S 115°11'49.58"E | E29: 545249203 | F29: 2000000 | G29: LAO | H29: KAR | I29: BALI | J29: TABANAN | K29: =VLOOKUP($B29,'WILL TOKO SEP'!A30:AK769,37,0) -> Baturiti | L29: DC | M29: M | N29: 0 | O29: 46196 | P29: 46217 | Q29: 0 | R29: =IFERROR(VLOOKUP($B29,JADWAL!$G$6:$J$690,4,0),"") | S29: =COUNTIF(N29:P29,"0") -> 1 | U29: TOKO EKSIS | V29: NON ZONA HITAM | X29: odi
A30: =A29+1 -> 29 | B30: F887 | C30: GUMBRIH - JEMBRANA | D30: S8 26 33.7 E114 52 43.3 | E30: 453902361 | F30: 2500000 | G30: JPT | H30: GNA | I30: BALI | J30: JEMBRANA | K30: =VLOOKUP($B30,'WILL TOKO SEP'!A31:AK770,37,0) -> #N/A | L30: DC | M30: M | N30: 46151 | O30: 46193 | P30: 0 | Q30: 0 | R30: =IFERROR(VLOOKUP($B30,JADWAL!$G$6:$J$690,4,0),"") | S30: =COUNTIF(N30:P30,"0") -> 1 | U30: TOKO EKSIS | V30: NON ZONA HITAM | X30: odi
A31: =A30+1 -> 30 | B31: F8DK | C31: MUDING BATU_BADUNG | D31: 8°38'32.69"S 115°10'40.02"E | E31: 439366645 | F31: 2000000 | G31: THR | H31: WWD | I31: BALI | J31: BADUNG | K31: =VLOOKUP($B31,'WILL TOKO SEP'!A32:AK771,37,0) -> Kuta Utara | L31: DC | M31: M | N31: 0 | O31: 0 | P31: 46218 | Q31: 0 | R31: =IFERROR(VLOOKUP($B31,JADWAL!$G$6:$J$690,4,0),"") | S31: =COUNTIF(N31:P31,"0") -> 2 | U31: TOKO EKSIS | V31: NON ZONA HITAM | X31: abdul
A32: =A31+1 -> 31 | B32: F8YX | C32: SESETAN NO .239 DPS | D32: 8°42'23.28"S 115°13'13.14"E | E32: 424461364 | F32: 3000000 | G32: THJ | H32: MRI | I32: BALI | J32: DENPASAR | K32: =VLOOKUP($B32,'WILL TOKO SEP'!A33:AK772,37,0) -> DENPASAR SELATAN | L32: IGR | M32: M | N32: 46168 | O32: 46192 | P32: 46226 | Q32: 46240 | R32: =IFERROR(VLOOKUP($B32,JADWAL!$G$6:$J$690,4,0),"") -> 46272 | S32: =COUNTIF(N32:P32,"0") -> 0 | U32: TOKO EKSIS | V32: ZONA HITAM | X32: #N/A
A33: =A32+1 -> 32 | B33: F91E | C33: TIGA - BANGLI | D33: S8 23 1.12 E115 21 14.12 | E33: 453934758 | F33: 2000000 | G33: JUN | H33: TSD | I33: BALI | J33: BANGLI | K33: =VLOOKUP($B33,'WILL TOKO SEP'!A34:AK773,37,0) -> SUSUT | L33: DC | M33: M | N33: 46146 | O33: 46186 | P33: 0 | Q33: 46245 | R33: =IFERROR(VLOOKUP($B33,JADWAL!$G$6:$J$690,4,0),"") | S33: =COUNTIF(N33:P33,"0") -> 1 | U33: TOKO EKSIS | V33: NON ZONA HITAM | X33: #N/A
A34: =A33+1 -> 33 | B34: F93J | C34: HAYAM WURUK NO.80_DPS | D34: 8°39'26.71"S 115°13'51.83"E | E34: 428184261 | F34: 2500000 | G34: DTO | H34: ANT | I34: BALI | J34: DENPASAR | K34: =VLOOKUP($B34,'WILL TOKO SEP'!A35:AK774,37,0) -> DENPASAR TIMUR | L34: IGR | M34: M | N34: 46163 | O34: 46200 | P34: 46218 | Q34: 46242 | R34: =IFERROR(VLOOKUP($B34,JADWAL!$G$6:$J$690,4,0),"") | S34: =COUNTIF(N34:P34,"0") -> 0 | U34: TOKO EKSIS | V34: ZONA HITAM | X34: #N/A
A35: =A34+1 -> 34 | B35: F9BL | C35: PC.PC.BELIMBING RICE TERRACE TBN | D35: 8°23'35.65"S 115° 2'10.80"E | E35: 484653236 | F35: 2000000 | G35: JPT | H35: GNA | I35: BALI | J35: TABANAN | K35: =VLOOKUP($B35,'WILL TOKO SEP'!A36:AK775,37,0) -> Pupuan | L35: DC | M35: M | N35: 46170 | O35: 0 | P35: 0 | Q35: 46237 | R35: =IFERROR(VLOOKUP($B35,JADWAL!$G$6:$J$690,4,0),"") | S35: =COUNTIF(N35:P35,"0") -> 2 | U35: TOKO EKSIS | V35: NON ZONA HITAM | X35: #N/A
A36: =A35+1 -> 35 | B36: F9FD | C36: GUNUNG SALAK - DENPASAR | D36: S8 40 06.2 E115 10 40.7 | E36: 522986175 | F36: 3000000 | G36: THR | H36: WWD | I36: BALI | J36: DENPASAR | K36: =VLOOKUP($B36,'WILL TOKO SEP'!A37:AK776,37,0) -> DENPASAR UTARA | L36: DC | M36: M | N36: 46171 | O36: 0 | P36: 46233 | Q36: 0 | R36: =IFERROR(VLOOKUP($B36,JADWAL!$G$6:$J$690,4,0),"") | S36: =COUNTIF(N36:P36,"0") -> 1 | U36: TOKO EKSIS | V36: NON ZONA HITAM | X36: 0
A37: =A36+1 -> 36 | B37: F9JZ | C37: GLOGOR CARIK - DENPASAR | D37: S8 42 8.26 E115 11 26.40 | E37: 401185504 | F37: 3000000 | G37: THJ | H37: LKH | I37: BALI | J37: DENPASAR | K37: =VLOOKUP($B37,'WILL TOKO SEP'!A38:AK777,37,0) -> DENPASAR SELATAN | L37: IGR | M37: M | N37: 0 | O37: 46179 | P37: 0 | Q37: 0 | R37: =IFERROR(VLOOKUP($B37,JADWAL!$G$6:$J$690,4,0),"") | S37: =COUNTIF(N37:P37,"0") -> 2 | U37: TOKO EKSIS | V37: NON ZONA HITAM | X37: pasek
A38: =A37+1 -> 37 | B38: FA5A | C38: SUDIMARA - TABANAN | D38: S8 34 17.67 E115 5 17.42 | E38: 443708301 | F38: 4500000 | G38: JPT | H38: INP | I38: BALI | J38: TABANAN | K38: =VLOOKUP($B38,'WILL TOKO SEP'!A39:AK778,37,0) -> TABANAN | L38: DC | M38: M | N38: 46160 | O38: 46191 | P38: 46230 | Q38: 46239 | R38: =IFERROR(VLOOKUP($B38,JADWAL!$G$6:$J$690,4,0),"") | S38: =COUNTIF(N38:P38,"0") -> 0 | U38: TOKO EKSIS | V38: ZONA HITAM | X38: #N/A
A39: =A38+1 -> 38 | B39: FA84 | C39: PC.PC.PURA BATUKARU_TBN | D39: 8°26'14.32"S 115° 7'38.71"E | E39: 767214282 | F39: 3000000 | G39: JPT | H39: STN | I39: BALI | J39: TABANAN | K39: =VLOOKUP($B39,'WILL TOKO SEP'!A40:AK779,37,0) -> PENEBEL | L39: DC | M39: M | N39: 0 | O39: 46176 | P39: 46213 | Q39: 0 | R39: =IFERROR(VLOOKUP($B39,JADWAL!$G$6:$J$690,4,0),"") | S39: =COUNTIF(N39:P39,"0") -> 1 | U39: TOKO EKSIS | V39: NON ZONA HITAM | X39: odi
A40: =A39+1 -> 39 | B40: FAAD | C40: KUKUH MARGA - TABANAN | D40: S8 30 49.6 E115 09 29.1 | E40: 504012853 | F40: 3000000 | G40: JPT | H40: SFH | I40: BALI | J40: TABANAN | K40: =VLOOKUP($B40,'WILL TOKO SEP'!A41:AK780,37,0) -> MARGA | L40: DC | M40: M | N40: 0 | O40: 46185 | P40: 0 | Q40: 46245 | R40: =IFERROR(VLOOKUP($B40,JADWAL!$G$6:$J$690,4,0),"") | S40: =COUNTIF(N40:P40,"0") -> 2 | U40: TOKO EKSIS | V40: NON ZONA HITAM | X40: #N/A
...

Sheet JADWAL
A1: CAB: BALI
A2: PEDOMAN JADWAL SO AUDIT BIC
A3: PERIODE : SEPTEMBER 2026
A4: NO | B4: TEAM | C4: GROUP | D4: PERSONIL | E4: HARI | F4: Jml Orang | G4: IDM | H4: TOKO | I4: STOCK RP | J4: TGL SO SEP | K4: Q/M | L4: KAS TOKO | M4: SO_AKTIVA | N4: ZONA | O4: KETERANGAN | P4: AS
A6: 1 | B6: TEAM 1 | C6: ANGGA RISTA | D6: YOGI SEPTA | E6: SELASA | G6: F01O | H6: =IF($G6<>"",VLOOKUP($G6,'MASTER TOKO BALI'!$B$2:$W$744,2,FALSE),"") -> SILIGITA - BADUNG | I6: =IF($G6<>"",VLOOKUP($G6,'MASTER TOKO BALI'!$B$2:$W$744,4,FALSE),"") -> 346801712 | J6: 46266 | K6: =IF($G6<>"",VLOOKUP($G6,'MASTER TOKO BALI'!$B$2:$W$744,12,FALSE),"") -> Q3 | L6: =IF($G6<>"",VLOOKUP($G6,'MASTER TOKO BALI'!$B$2:$W$744,5,FALSE),"") -> 2500000 | N6: =IF($G6<>"",VLOOKUP($G6,'MASTER TOKO BALI'!$B$2:$W$744,21,FALSE),"") -> NON ZONA HITAM | P6: =IF($G6<>"",VLOOKUP($G6,'MASTER TOKO BALI'!$B$2:$W$740,7,FALSE),"") -> ARH
A7: =A6+1 -> 2 | B7: TEAM GABUNG | C7: ANGGA RISTA | D7: ANGGA EKSTRA | E7: SELASA | G7: TA5A | H7: =IF($G7<>"",VLOOKUP($G7,'MASTER TOKO BALI'!$B$2:$W$744,2,FALSE),"") -> PURI GADING - BADUNG | I7: =IF($G7<>"",VLOOKUP($G7,'MASTER TOKO BALI'!$B$2:$W$744,4,FALSE),"") -> 327518718 | J7: 46266 | K7: =IF($G7<>"",VLOOKUP($G7,'MASTER TOKO BALI'!$B$2:$W$744,12,FALSE),"") -> Q3 | L7: =IF($G7<>"",VLOOKUP($G7,'MASTER TOKO BALI'!$B$2:$W$744,5,FALSE),"") -> 3000000 | N7: =IF($G7<>"",VLOOKUP($G7,'MASTER TOKO BALI'!$B$2:$W$744,21,FALSE),"") -> NON ZONA HITAM | P7: =IF($G7<>"",VLOOKUP($G7,'MASTER TOKO BALI'!$B$2:$W$740,7,FALSE),"") -> DDY
A8: =A7+1 -> 3 | B8: TEAM 2 | C8: ANGGA RISTA | D8: CAHYO | E8: SELASA | G8: TL5C | H8: =IF($G8<>"",VLOOKUP($G8,'MASTER TOKO BALI'!$B$2:$W$744,2,FALSE),"") -> KUTA - BADUNG | I8: =IF($G8<>"",VLOOKUP($G8,'MASTER TOKO BALI'!$B$2:$W$744,4,FALSE),"") -> 295576035 | J8: 46266 | K8: =IF($G8<>"",VLOOKUP($G8,'MASTER TOKO BALI'!$B$2:$W$744,12,FALSE),"") -> Q3 | L8: =IF($G8<>"",VLOOKUP($G8,'MASTER TOKO BALI'!$B$2:$W$744,5,FALSE),"") -> 2000000 | N8: =IF($G8<>"",VLOOKUP($G8,'MASTER TOKO BALI'!$B$2:$W$744,21,FALSE),"") -> NON ZONA HITAM | P8: =IF($G8<>"",VLOOKUP($G8,'MASTER TOKO BALI'!$B$2:$W$740,7,FALSE),"") -> DMA
A9: =A8+1 -> 4 | B9: TEAM GABUNG | C9: ANGGA RISTA | D9: ANGGA EKSTRA | E9: SELASA | G9: TXXC | H9: =IF($G9<>"",VLOOKUP($G9,'MASTER TOKO BALI'!$B$2:$W$744,2,FALSE),"") -> YCG.NAKULA 93 - BADUNG | I9: =IF($G9<>"",VLOOKUP($G9,'MASTER TOKO BALI'!$B$2:$W$744,4,FALSE),"") -> 448923703 | J9: 46266 | K9: =IF($G9<>"",VLOOKUP($G9,'MASTER TOKO BALI'!$B$2:$W$744,12,FALSE),"") -> Q3 | L9: =IF($G9<>"",VLOOKUP($G9,'MASTER TOKO BALI'!$B$2:$W$744,5,FALSE),"") -> 2000000 | N9: =IF($G9<>"",VLOOKUP($G9,'MASTER TOKO BALI'!$B$2:$W$744,21,FALSE),"") -> NON ZONA HITAM | P9: =IF($G9<>"",VLOOKUP($G9,'MASTER TOKO BALI'!$B$2:$W$740,7,FALSE),"") -> NHY
A10: =A9+1 -> 5 | B10: TEAM 3 | C10: ODI TRI | D10: BAGUS MAULANA | E10: SELASA | G10: TK4R | H10: =IF($G10<>"",VLOOKUP($G10,'MASTER TOKO BALI'!$B$2:$W$744,2,FALSE),"") -> YEH GANGGA SUDIMARA_TABANAN | I10: =IF($G10<>"",VLOOKUP($G10,'MASTER TOKO BALI'!$B$2:$W$744,4,FALSE),"") -> 384207357 | J10: 46266 | K10: =IF($G10<>"",VLOOKUP($G10,'MASTER TOKO BALI'!$B$2:$W$744,12,FALSE),"") -> Q3 | L10: =IF($G10<>"",VLOOKUP($G10,'MASTER TOKO BALI'!$B$2:$W$744,5,FALSE),"") -> 2000000 | N10: =IF($G10<>"",VLOOKUP($G10,'MASTER TOKO BALI'!$B$2:$W$744,21,FALSE),"") -> NON ZONA HITAM | P10: =IF($G10<>"",VLOOKUP($G10,'MASTER TOKO BALI'!$B$2:$W$740,7,FALSE),"") -> INP
A11: =A10+1 -> 6 | B11: TEAM GABUNG | C11: ODI TRI | D11: ODI TRI EKSTRA | E11: SELASA | G11: TKPE | H11: =IF($G11<>"",VLOOKUP($G11,'MASTER TOKO BALI'!$B$2:$W$744,2,FALSE),"") -> PANDAK BANDUNG - TABANAN | I11: =IF($G11<>"",VLOOKUP($G11,'MASTER TOKO BALI'!$B$2:$W$744,4,FALSE),"") -> 332707225 | J11: 46266 | K11: =IF($G11<>"",VLOOKUP($G11,'MASTER TOKO BALI'!$B$2:$W$744,12,FALSE),"") -> Q3 | L11: =IF($G11<>"",VLOOKUP($G11,'MASTER TOKO BALI'!$B$2:$W$744,5,FALSE),"") -> 2500000 | N11: =IF($G11<>"",VLOOKUP($G11,'MASTER TOKO BALI'!$B$2:$W$744,21,FALSE),"") -> NON ZONA HITAM | P11: =IF($G11<>"",VLOOKUP($G11,'MASTER TOKO BALI'!$B$2:$W$740,7,FALSE),"") -> ERI
A12: =A11+1 -> 7 | B12: TEAM 4 | C12: ODI TRI | D12: RUDIARTA | E12: SELASA | G12: FIUT | H12: =IF($G12<>"",VLOOKUP($G12,'MASTER TOKO BALI'!$B$2:$W$744,2,FALSE),"") -> SURABRATA - TABANAN | I12: =IF($G12<>"",VLOOKUP($G12,'MASTER TOKO BALI'!$B$2:$W$744,4,FALSE),"") -> 460612111 | J12: 46266 | K12: =IF($G12<>"",VLOOKUP($G12,'MASTER TOKO BALI'!$B$2:$W$744,12,FALSE),"") -> Q3 | L12: =IF($G12<>"",VLOOKUP($G12,'MASTER TOKO BALI'!$B$2:$W$744,5,FALSE),"") -> 3000000 | N12: =IF($G12<>"",VLOOKUP($G12,'MASTER TOKO BALI'!$B$2:$W$744,21,FALSE),"") -> NON ZONA HITAM | P12: =IF($G12<>"",VLOOKUP($G12,'MASTER TOKO BALI'!$B$2:$W$740,7,FALSE),"") -> GNA
A13: =A12+1 -> 8 | B13: TEAM GABUNG | C13: ODI TRI | D13: ODI TRI EKSTRA | E13: SELASA | G13: FQUA | H13: =IF($G13<>"",VLOOKUP($G13,'MASTER TOKO BALI'!$B$2:$W$744,2,FALSE),"") -> ANTOSARI - TABANAN | I13: =IF($G13<>"",VLOOKUP($G13,'MASTER TOKO BALI'!$B$2:$W$744,4,FALSE),"") -> 370556278 | J13: 46266 | K13: =IF($G13<>"",VLOOKUP($G13,'MASTER TOKO BALI'!$B$2:$W$744,12,FALSE),"") -> M | L13: =IF($G13<>"",VLOOKUP($G13,'MASTER TOKO BALI'!$B$2:$W$744,5,FALSE),"") -> 2000000 | N13: =IF($G13<>"",VLOOKUP($G13,'MASTER TOKO BALI'!$B$2:$W$744,21,FALSE),"") -> NON ZONA HITAM | P13: =IF($G13<>"",VLOOKUP($G13,'MASTER TOKO BALI'!$B$2:$W$740,7,FALSE),"") -> GNA
A14: =A13+1 -> 9 | B14: TEAM 5 | C14: ANGGA ARDIAN | D14: RAFLI | E14: SELASA | G14: TFOD | H14: =IF($G14<>"",VLOOKUP($G14,'MASTER TOKO BALI'!$B$2:$W$744,2,FALSE),"") -> PALGUNA NO 101X-GYR | I14: =IF($G14<>"",VLOOKUP($G14,'MASTER TOKO BALI'!$B$2:$W$744,4,FALSE),"") -> 356731825 | J14: 46266 | K14: =IF($G14<>"",VLOOKUP($G14,'MASTER TOKO BALI'!$B$2:$W$744,12,FALSE),"") -> M | L14: =IF($G14<>"",VLOOKUP($G14,'MASTER TOKO BALI'!$B$2:$W$744,5,FALSE),"") -> 2500000 | N14: =IF($G14<>"",VLOOKUP($G14,'MASTER TOKO BALI'!$B$2:$W$744,21,FALSE),"") -> NON ZONA HITAM | P14: =IF($G14<>"",VLOOKUP($G14,'MASTER TOKO BALI'!$B$2:$W$740,7,FALSE),"") -> IPM
A15: =A14+1 -> 10 | B15: TEAM GABUNG | C15: ANGGA ARDIAN | D15: ANGGA AR EXTRA | E15: SELASA | G15: FAVO | H15: =IF($G15<>"",VLOOKUP($G15,'MASTER TOKO BALI'!$B$2:$W$744,2,FALSE),"") -> BATU BULAN 2 - GIANYAR | I15: =IF($G15<>"",VLOOKUP($G15,'MASTER TOKO BALI'!$B$2:$W$744,4,FALSE),"") -> 373193234 | J15: 46266 | K15: =IF($G15<>"",VLOOKUP($G15,'MASTER TOKO BALI'!$B$2:$W$744,12,FALSE),"") -> M | L15: =IF($G15<>"",VLOOKUP($G15,'MASTER TOKO BALI'!$B$2:$W$744,5,FALSE),"") -> 2500000 | N15: =IF($G15<>"",VLOOKUP($G15,'MASTER TOKO BALI'!$B$2:$W$744,21,FALSE),"") -> NON ZONA HITAM | P15: =IF($G15<>"",VLOOKUP($G15,'MASTER TOKO BALI'!$B$2:$W$740,7,FALSE),"") -> IPM
A16: =A15+1 -> 11 | B16: TEAM 6 | C16: ANGGA ARDIAN | D16: KADEK GALANG | E16: SELASA | G16: FXXM | H16: =IF($G16<>"",VLOOKUP($G16,'MASTER TOKO BALI'!$B$2:$W$744,2,FALSE),"") -> CANGI - GIANYAR | I16: =IF($G16<>"",VLOOKUP($G16,'MASTER TOKO BALI'!$B$2:$W$744,4,FALSE),"") -> 363354534 | J16: 46266 | K16: =IF($G16<>"",VLOOKUP($G16,'MASTER TOKO BALI'!$B$2:$W$744,12,FALSE),"") -> Q3 | L16: =IF($G16<>"",VLOOKUP($G16,'MASTER TOKO BALI'!$B$2:$W$744,5,FALSE),"") -> 2000000 | N16: =IF($G16<>"",VLOOKUP($G16,'MASTER TOKO BALI'!$B$2:$W$744,21,FALSE),"") -> NON ZONA HITAM | P16: =IF($G16<>"",VLOOKUP($G16,'MASTER TOKO BALI'!$B$2:$W$740,7,FALSE),"") -> MRS
A17: =A16+1 -> 12 | B17: TEAM GABUNG | C17: ANGGA ARDIAN | D17: ANGGA AR EXTRA | E17: SELASA | G17: FMRO | H17: =IF($G17<>"",VLOOKUP($G17,'MASTER TOKO BALI'!$B$2:$W$744,2,FALSE),"") -> SMKI NO.46 GIANYAR | I17: =IF($G17<>"",VLOOKUP($G17,'MASTER TOKO BALI'!$B$2:$W$744,4,FALSE),"") -> 421809650 | J17: 46266 | K17: =IF($G17<>"",VLOOKUP($G17,'MASTER TOKO BALI'!$B$2:$W$744,12,FALSE),"") -> Q3 | L17: =IF($G17<>"",VLOOKUP($G17,'MASTER TOKO BALI'!$B$2:$W$744,5,FALSE),"") -> 2000000 | N17: =IF($G17<>"",VLOOKUP($G17,'MASTER TOKO BALI'!$B$2:$W$744,21,FALSE),"") -> NON ZONA HITAM | P17: =IF($G17<>"",VLOOKUP($G17,'MASTER TOKO BALI'!$B$2:$W$740,7,FALSE),"") -> IPM
A18: =A17+1 -> 13 | B18: TEAM 7 | C18: ABDUL | D18: JULIANTO | E18: SELASA | G18: TQ3N | H18: =IF($G18<>"",VLOOKUP($G18,'MASTER TOKO BALI'!$B$2:$W$744,2,FALSE),"") -> YCG.TUNJUNG KAPAL DUA - BDG | I18: =IF($G18<>"",VLOOKUP($G18,'MASTER TOKO BALI'!$B$2:$W$744,4,FALSE),"") -> 490303666 | J18: 46266 | K18: =IF($G18<>"",VLOOKUP($G18,'MASTER TOKO BALI'!$B$2:$W$744,12,FALSE),"") -> Q3 | L18: =IF($G18<>"",VLOOKUP($G18,'MASTER TOKO BALI'!$B$2:$W$744,5,FALSE),"") -> 2500000 | N18: =IF($G18<>"",VLOOKUP($G18,'MASTER TOKO BALI'!$B$2:$W$744,21,FALSE),"") -> NON ZONA HITAM | P18: =IF($G18<>"",VLOOKUP($G18,'MASTER TOKO BALI'!$B$2:$W$740,7,FALSE),"") -> JSR
... A24: =A23+1 -> 19 | B24: TEAM 10 | C24: PASEK | D24: M.LUTFI | E24: SELASA | G24: TLFV | H24: =IF($G24<>"",VLOOKUP($G24,'MASTER TOKO BALI'!$B$2:$W$744,2,FALSE),"") -> PC.PC.DIPONEGORO_DPS | I24: =IF($G24<>"",VLOOKUP($G24,'MASTER TOKO BALI'!$B$2:$W$744,4,FALSE),"") -> 511623137 | J24: 46266 | K24: =IF($G24<>"",VLOOKUP($G24,'MASTER TOKO BALI'!$B$2:$W$744,12,FALSE),"") -> M | L24: =IF($G24<>"",VLOOKUP($G24,'MASTER TOKO BALI'!$B$2:$W$744,5,FALSE),"") -> 4000000 | N24: =IF($G24<>"",VLOOKUP($G24,'MASTER TOKO BALI'!$B$2:$W$744,21,FALSE),"") -> NON ZONA HITAM | P24: =IF($G24<>"",VLOOKUP($G24,'MASTER TOKO BALI'!$B$2:$W$740,7,FALSE),"") -> MRI
A25: =A24+1 -> 20 | B25: TIM GABUNG | C25: PASEK | D25: PASEK EKSTRA | E25: SELASA | H25: =IF($G25<>"",VLOOKUP($G25,'MASTER TOKO BALI'!$B$2:$W$744,2,FALSE),"") | I25: =IF($G25<>"",VLOOKUP($G25,'MASTER TOKO BALI'!$B$2:$W$744,4,FALSE),"") | J25: 46266 | K25: =IF($G25<>"",VLOOKUP($G25,'MASTER TOKO BALI'!$B$2:$W$744,12,FALSE),"") | L25: =IF($G25<>"",VLOOKUP($G25,'MASTER TOKO BALI'!$B$2:$W$744,5,FALSE),"") | N25: =IF($G25<>"",VLOOKUP($G25,'MASTER TOKO BALI'!$B$2:$W$744,21,FALSE),"") | P25: =IF($G25<>"",VLOOKUP($G25,'MASTER TOKO BALI'!$B$2:$W$740,7,FALSE),"")
A26: =A25+1 -> 21 | B26: TEAM 11 | C26: BISMA | D26: BUJANGGA | E26: SELASA | G26: TYP6 | H26: =IF($G26<>"",VLOOKUP($G26,'MASTER TOKO BALI'!$B$2:$W$744,2,FALSE),"") -> RAYA TUKAD BALIAN - DENPASAR | I26: =IF($G26<>"",VLOOKUP($G26,'MASTER TOKO BALI'!$B$2:$W$744,4,FALSE),"") -> 364538918 | J26: 46266 | K26: =IF($G26<>"",VLOOKUP($G26,'MASTER TOKO BALI'!$B$2:$W$744,12,FALSE),"") -> Q3 | L26: =IF($G26<>"",VLOOKUP($G26,'MASTER TOKO BALI'!$B$2:$W$744,5,FALSE),"") -> 2000000 | N26: =IF($G26<>"",VLOOKUP($G26,'MASTER TOKO BALI'!$B$2:$W$744,21,FALSE),"") -> NON ZONA HITAM | P26: =IF($G26<>"",VLOOKUP($G26,'MASTER TOKO BALI'!$B$2:$W$740,7,FALSE),"") -> ANT
A27: =A26+1 -> 22 | B27: TIM GABUNG | C27: BISMA | D27: BISMA EKSTRA | E27: SELASA | G27: FCHN | H27: =IF($G27<>"",VLOOKUP($G27,'MASTER TOKO BALI'!$B$2:$W$744,2,FALSE),"") -> BATUR SARI_ DPS | I27: =IF($G27<>"",VLOOKUP($G27,'MASTER TOKO BALI'!$B$2:$W$744,4,FALSE),"") -> 383814995 | J27: 46266 | K27: =IF($G27<>"",VLOOKUP($G27,'MASTER TOKO BALI'!$B$2:$W$744,12,FALSE),"") -> Q3 | L27: =IF($G27<>"",VLOOKUP($G27,'MASTER TOKO BALI'!$B$2:$W$744,5,FALSE),"") -> 2000000 | N27: =IF($G27<>"",VLOOKUP($G27,'MASTER TOKO BALI'!$B$2:$W$744,21,FALSE),"") -> NON ZONA HITAM | P27: =IF($G27<>"",VLOOKUP($G27,'MASTER TOKO BALI'!$B$2:$W$740,7,FALSE),"") -> IGN
A28: =A27+1 -> 23 | B28: TEAM 12 | C28: BISMA | D28: GEDE ARIASA | E28: SELASA | G28: TVUK | H28: =IF($G28<>"",VLOOKUP($G28,'MASTER TOKO BALI'!$B$2:$W$744,2,FALSE),"") -> YCG.RAYA DESA - SINGARAJA | I28: =IF($G28<>"",VLOOKUP($G28,'MASTER TOKO BALI'!$B$2:$W$744,4,FALSE),"") -> 499159652 | J28: 46266 | K28: =IF($G28<>"",VLOOKUP($G28,'MASTER TOKO BALI'!$B$2:$W$744,12,FALSE),"") -> Q3 | L28: =IF($G28<>"",VLOOKUP($G28,'MASTER TOKO BALI'!$B$2:$W$744,5,FALSE),"") -> 2000000 | N28: =IF($G28<>"",VLOOKUP($G28,'MASTER TOKO BALI'!$B$2:$W$744,21,FALSE),"") -> NON ZONA HITAM | P28: =IF($G28<>"",VLOOKUP($G28,'MASTER TOKO BALI'!$B$2:$W$740,7,FALSE),"") -> MAH
A29: =A28+1 -> 24 | B29: TIM GABUNG | C29: BISMA | D29: BISMA EKSTRA | E29: SELASA | G29: FIMD | H29: =IF($G29<>"",VLOOKUP($G29,'MASTER TOKO BALI'!$B$2:$W$744,2,FALSE),"") -> RAYA SANGSIT - SINGARAJA | I29: =IF($G29<>"",VLOOKUP($G29,'MASTER TOKO BALI'!$B$2:$W$744,4,FALSE),"") -> 443856478 | J29: 46266 | K29: =IF($G29<>"",VLOOKUP($G29,'MASTER TOKO BALI'!$B$2:$W$744,12,FALSE),"") -> Q3 | L29: =IF($G29<>"",VLOOKUP($G29,'MASTER TOKO BALI'!$B$2:$W$744,5,FALSE),"") -> 2000000 | N29: =IF($G29<>"",VLOOKUP($G29,'MASTER TOKO BALI'!$B$2:$W$744,21,FALSE),"") -> NON ZONA HITAM | P29: =IF($G29<>"",VLOOKUP($G29,'MASTER TOKO BALI'!$B$2:$W$740,7,FALSE),"") -> MAH
I30: =IF($G30<>"",VLOOKUP($G30,'MASTER TOKO BALI'!$B$2:$W$744,4,FALSE),"") | K30: =IF($G30<>"",VLOOKUP($G30,'MASTER TOKO BALI'!$B$2:$W$744,12,FALSE),"") | L30: =IF($G30<>"",VLOOKUP($G30,'MASTER TOKO BALI'!$B$2:$W$744,5,FALSE),"") | N30: =IF($G30<>"",VLOOKUP($G30,'MASTER TOKO BALI'!$B$2:$W$744,21,FALSE),"") | P30: =IF($G30<>"",VLOOKUP($G30,'MASTER TOKO BALI'!$B$2:$W$740,7,FALSE),"")
A31: =A29+1 -> 25 | B31: TEAM 1 | C31: ANGGA RISTA | D31: YOGI SEPTA | E31: MINGGU | I31: =IF($G31<>"",VLOOKUP($G31,'MASTER TOKO BALI'!$B$2:$W$744,4,FALSE),"") | K31: =IF($G31<>"",VLOOKUP($G31,'MASTER TOKO BALI'!$B$2:$W$744,12,FALSE),"") | L31: =IF($G31<>"",VLOOKUP($G31,'MASTER TOKO BALI'!$B$2:$W$744,5,FALSE),"") | N31: =IF($G31<>"",VLOOKUP($G31,'MASTER TOKO BALI'!$B$2:$W$744,21,FALSE),"") | P31: =IF($G31<>"",VLOOKUP($G31,'MASTER TOKO BALI'!$B$2:$W$740,7,FALSE),"")
A32: =A31+1 -> 26 | B32: TEAM GABUNG | C32: ANGGA RISTA | D32: ANGGA EKSTRA | E32: MINGGU | I32: =IF($G32<>"",VLOOKUP($G32,'MASTER TOKO BALI'!$B$2:$W$744,4,FALSE),"") | K32: =IF($G32<>"",VLOOKUP($G32,'MASTER TOKO BALI'!$B$2:$W$744,12,FALSE),"") | L32: =IF($G32<>"",VLOOKUP($G32,'MASTER TOKO BALI'!$B$2:$W$744,5,FALSE),"") | N32: =IF($G32<>"",VLOOKUP($G32,'MASTER TOKO BALI'!$B$2:$W$744,21,FALSE),"") | P32: =IF($G32<>"",VLOOKUP($G32,'MASTER TOKO BALI'!$B$2:$W$740,7,FALSE),"")
A33: =A32+1 -> 27 | B33: TEAM 2 | C33: ANGGA RISTA | D33: CAHYO | E33: MINGGU | I33: =IF($G33<>"",VLOOKUP($G33,'MASTER TOKO BALI'!$B$2:$W$744,4,FALSE),"") | K33: =IF($G33<>"",VLOOKUP($G33,'MASTER TOKO BALI'!$B$2:$W$744,12,FALSE),"") | L33: =IF($G33<>"",VLOOKUP($G33,'MASTER TOKO BALI'!$B$2:$W$744,5,FALSE),"") | N33: =IF($G33<>"",VLOOKUP($G33,'MASTER TOKO BALI'!$B$2:$W$744,21,FALSE),"") | P33: =IF($G33<>"",VLOOKUP($G33,'MASTER TOKO BALI'!$B$2:$W$740,7,FALSE),"")
A34: =A33+1 -> 28 | B34: TEAM GABUNG | C34: ANGGA RISTA | D34: ANGGA EKSTRA | E34: MINGGU | I34: =IF($G34<>"",VLOOKUP($G34,'MASTER TOKO BALI'!$B$2:$W$744,4,FALSE),"") | K34: =IF($G34<>"",VLOOKUP($G34,'MASTER TOKO BALI'!$B$2:$W$744,12,FALSE),"") | L34: =IF($G34<>"",VLOOKUP($G34,'MASTER TOKO BALI'!$B$2:$W$744,5,FALSE),"") | N34: =IF($G34<>"",VLOOKUP($G34,'MASTER TOKO BALI'!$B$2:$W$744,21,FALSE),"") | P34: =IF($G34<>"",VLOOKUP($G34,'MASTER TOKO BALI'!$B$2:$W$740,7,FALSE),"")
A35: =A34+1 -> 29 | B35: TEAM 3 | C35: ODI TRI | D35: BAGUS MAULANA | E35: MINGGU | I35: =IF($G35<>"",VLOOKUP($G35,'MASTER TOKO BALI'!$B$2:$W$744,4,FALSE),"") | K35: =IF($G35<>"",VLOOKUP($G35,'MASTER TOKO BALI'!$B$2:$W$744,12,FALSE),"") | L35: =IF($G35<>"",VLOOKUP($G35,'MASTER TOKO BALI'!$B$2:$W$744,5,FALSE),"") | N35: =IF($G35<>"",VLOOKUP($G35,'MASTER TOKO BALI'!$B$2:$W$744,21,FALSE),"") | P35: =IF($G35<>"",VLOOKUP($G35,'MASTER TOKO BALI'!$B$2:$W$740,7,FALSE),"")
A36: =A35+1 -> 30 | B36: TEAM GABUNG | C36: ODI TRI | D36: ODI TRI EKSTRA | E36: MINGGU | I36: =IF($G36<>"",VLOOKUP($G36,'MASTER TOKO BALI'!$B$2:$W$744,4,FALSE),"") | K36: =IF($G36<>"",VLOOKUP($G36,'MASTER TOKO BALI'!$B$2:$W$744,12,FALSE),"") | L36: =IF($G36<>"",VLOOKUP($G36,'MASTER TOKO BALI'!$B$2:$W$744,5,FALSE),"") | N36: =IF($G36<>"",VLOOKUP($G36,'MASTER TOKO BALI'!$B$2:$W$744,21,FALSE),"") | P36: =IF($G36<>"",VLOOKUP($G36,'MASTER TOKO BALI'!$B$2:$W$740,7,FALSE),"")
A37: =A36+1 -> 31 | B37: TEAM 4 | C37: ODI TRI | D37: RUDIARTA | E37: MINGGU | I37: =IF($G37<>"",VLOOKUP($G37,'MASTER TOKO BALI'!$B$2:$W$744,4,FALSE),"") | K37: =IF($G37<>"",VLOOKUP($G37,'MASTER TOKO BALI'!$B$2:$W$744,12,FALSE),"") | L37: =IF($G37<>"",VLOOKUP($G37,'MASTER TOKO BALI'!$B$2:$W$744,5,FALSE),"") | N37: =IF($G37<>"",VLOOKUP($G37,'MASTER TOKO BALI'!$B$2:$W$744,21,FALSE),"") | P37: =IF($G37<>"",VLOOKUP($G37,'MASTER TOKO BALI'!$B$2:$W$740,7,FALSE),"")
A38: =A37+1 -> 32 | B38: TEAM GABUNG | C38: ODI TRI | D38: ODI TRI EKSTRA | E38: MINGGU | I38: =IF($G38<>"",VLOOKUP($G38,'MASTER TOKO BALI'!$B$2:$W$744,4,FALSE),"") | K38: =IF($G38<>"",VLOOKUP($G38,'MASTER TOKO BALI'!$B$2:$W$744,12,FALSE),"") | L38: =IF($G38<>"",VLOOKUP($G38,'MASTER TOKO BALI'!$B$2:$W$744,5,FALSE),"") | N38: =IF($G38<>"",VLOOKUP($G38,'MASTER TOKO BALI'!$B$2:$W$744,21,FALSE),"") | P38: =IF($G38<>"",VLOOKUP($G38,'MASTER TOKO BALI'!$B$2:$W$740,7,FALSE),"")
